{
 "cells": [
  {
   "cell_type": "code",
   "execution_count": 50,
   "id": "0469496c-61af-46fd-963d-b01e5aa7b6ca",
   "metadata": {},
   "outputs": [],
   "source": [
    "import os\n",
    "import tensorflow as tf\n",
    "from tensorflow import keras\n",
    "from keras.models import load_model\n",
    "from PIL import Image\n",
    "import numpy as np\n",
    "import torch\n",
    "from torchvision import transforms\n",
    "from PIL import Image"
   ]
  },
  {
   "cell_type": "code",
   "execution_count": 2,
   "id": "5b73a885-979c-4b8c-9123-6015b314febe",
   "metadata": {},
   "outputs": [
    {
     "name": "stdout",
     "output_type": "stream",
     "text": [
      "WARNING:tensorflow:From C:\\Users\\dalet\\anaconda3\\Lib\\site-packages\\keras\\src\\backend.py:1398: The name tf.executing_eagerly_outside_functions is deprecated. Please use tf.compat.v1.executing_eagerly_outside_functions instead.\n",
      "\n",
      "WARNING:tensorflow:From C:\\Users\\dalet\\anaconda3\\Lib\\site-packages\\keras\\src\\layers\\pooling\\max_pooling2d.py:161: The name tf.nn.max_pool is deprecated. Please use tf.nn.max_pool2d instead.\n",
      "\n"
     ]
    }
   ],
   "source": [
    "model = load_model('model1.h5')"
   ]
  },
  {
   "cell_type": "code",
   "execution_count": 47,
   "id": "163b2853-6690-4fbd-972a-3981444a94eb",
   "metadata": {},
   "outputs": [],
   "source": [
    "path = \"predict/ISIC_0000002.png\""
   ]
  },
  {
   "cell_type": "code",
   "execution_count": 51,
   "id": "6e2aff12-94d5-42e3-9001-6ec5036c645b",
   "metadata": {},
   "outputs": [],
   "source": [
    "img = tf.keras.utils.load_img(path)\n",
    "\n",
    "transform = transforms.Compose([ \n",
    "    transforms.PILToTensor() \n",
    "]) \n",
    "\n",
    "img_tensor = transform(img) "
   ]
  },
  {
   "cell_type": "code",
   "execution_count": 61,
   "id": "72ef07a0-c825-4f9b-b33f-d9da74daefb6",
   "metadata": {},
   "outputs": [
    {
     "data": {
      "text/plain": [
       "array([[[255, 255, 255],\n",
       "        [228, 228, 228],\n",
       "        [255, 255, 255],\n",
       "        ...,\n",
       "        [255, 255, 255],\n",
       "        [240, 240, 240],\n",
       "        [255, 255, 255]],\n",
       "\n",
       "       [[224, 224, 224],\n",
       "        [ 43,  43,  43],\n",
       "        [ 21,  21,  21],\n",
       "        ...,\n",
       "        [  4,   4,   4],\n",
       "        [ 24,  24,  24],\n",
       "        [217, 217, 217]],\n",
       "\n",
       "       [[255, 255, 255],\n",
       "        [  0,   0,   0],\n",
       "        [  0,   0,   0],\n",
       "        ...,\n",
       "        [  0,   0,   0],\n",
       "        [  3,   3,   3],\n",
       "        [255, 255, 255]],\n",
       "\n",
       "       ...,\n",
       "\n",
       "       [[255, 255, 255],\n",
       "        [ 26,  26,  28],\n",
       "        [  5,   5,   7],\n",
       "        ...,\n",
       "        [ 15,  20,  24],\n",
       "        [  4,   8,  11],\n",
       "        [252, 255, 255]],\n",
       "\n",
       "       [[225, 225, 227],\n",
       "        [ 39,  39,  41],\n",
       "        [  0,   0,   2],\n",
       "        ...,\n",
       "        [ 20,  25,  28],\n",
       "        [ 15,  21,  21],\n",
       "        [224, 228, 227]],\n",
       "\n",
       "       [[255, 255, 255],\n",
       "        [231, 231, 233],\n",
       "        [255, 255, 255],\n",
       "        ...,\n",
       "        [245, 251, 251],\n",
       "        [217, 223, 221],\n",
       "        [251, 255, 253]]], dtype=uint8)"
      ]
     },
     "execution_count": 61,
     "metadata": {},
     "output_type": "execute_result"
    }
   ],
   "source": [
    "img_array = np.array(img)\n",
    "\n",
    "img_array"
   ]
  },
  {
   "cell_type": "code",
   "execution_count": 60,
   "id": "a5da9fbf-a185-4282-8c10-61e00e717902",
   "metadata": {},
   "outputs": [
    {
     "ename": "ValueError",
     "evalue": "in user code:\n\n    File \"C:\\Users\\dalet\\anaconda3\\Lib\\site-packages\\keras\\src\\engine\\training.py\", line 2440, in predict_function  *\n        return step_function(self, iterator)\n    File \"C:\\Users\\dalet\\anaconda3\\Lib\\site-packages\\keras\\src\\engine\\training.py\", line 2425, in step_function  **\n        outputs = model.distribute_strategy.run(run_step, args=(data,))\n    File \"C:\\Users\\dalet\\anaconda3\\Lib\\site-packages\\keras\\src\\engine\\training.py\", line 2413, in run_step  **\n        outputs = model.predict_step(data)\n    File \"C:\\Users\\dalet\\anaconda3\\Lib\\site-packages\\keras\\src\\engine\\training.py\", line 2381, in predict_step\n        return self(x, training=False)\n    File \"C:\\Users\\dalet\\anaconda3\\Lib\\site-packages\\keras\\src\\utils\\traceback_utils.py\", line 70, in error_handler\n        raise e.with_traceback(filtered_tb) from None\n    File \"C:\\Users\\dalet\\anaconda3\\Lib\\site-packages\\keras\\src\\engine\\input_spec.py\", line 298, in assert_input_compatibility\n        raise ValueError(\n\n    ValueError: Input 0 of layer \"sequential\" is incompatible with the layer: expected shape=(None, 300, 300, 3), found shape=(None, 1022, 3)\n",
     "output_type": "error",
     "traceback": [
      "\u001b[1;31m---------------------------------------------------------------------------\u001b[0m",
      "\u001b[1;31mValueError\u001b[0m                                Traceback (most recent call last)",
      "Cell \u001b[1;32mIn[60], line 1\u001b[0m\n\u001b[1;32m----> 1\u001b[0m model\u001b[38;5;241m.\u001b[39mpredict(img_array)\n",
      "File \u001b[1;32m~\\anaconda3\\Lib\\site-packages\\keras\\src\\utils\\traceback_utils.py:70\u001b[0m, in \u001b[0;36mfilter_traceback.<locals>.error_handler\u001b[1;34m(*args, **kwargs)\u001b[0m\n\u001b[0;32m     67\u001b[0m     filtered_tb \u001b[38;5;241m=\u001b[39m _process_traceback_frames(e\u001b[38;5;241m.\u001b[39m__traceback__)\n\u001b[0;32m     68\u001b[0m     \u001b[38;5;66;03m# To get the full stack trace, call:\u001b[39;00m\n\u001b[0;32m     69\u001b[0m     \u001b[38;5;66;03m# `tf.debugging.disable_traceback_filtering()`\u001b[39;00m\n\u001b[1;32m---> 70\u001b[0m     \u001b[38;5;28;01mraise\u001b[39;00m e\u001b[38;5;241m.\u001b[39mwith_traceback(filtered_tb) \u001b[38;5;28;01mfrom\u001b[39;00m \u001b[38;5;28;01mNone\u001b[39;00m\n\u001b[0;32m     71\u001b[0m \u001b[38;5;28;01mfinally\u001b[39;00m:\n\u001b[0;32m     72\u001b[0m     \u001b[38;5;28;01mdel\u001b[39;00m filtered_tb\n",
      "File \u001b[1;32m~\\AppData\\Local\\Temp\\__autograph_generated_file_ua8ktul.py:15\u001b[0m, in \u001b[0;36mouter_factory.<locals>.inner_factory.<locals>.tf__predict_function\u001b[1;34m(iterator)\u001b[0m\n\u001b[0;32m     13\u001b[0m \u001b[38;5;28;01mtry\u001b[39;00m:\n\u001b[0;32m     14\u001b[0m     do_return \u001b[38;5;241m=\u001b[39m \u001b[38;5;28;01mTrue\u001b[39;00m\n\u001b[1;32m---> 15\u001b[0m     retval_ \u001b[38;5;241m=\u001b[39m ag__\u001b[38;5;241m.\u001b[39mconverted_call(ag__\u001b[38;5;241m.\u001b[39mld(step_function), (ag__\u001b[38;5;241m.\u001b[39mld(\u001b[38;5;28mself\u001b[39m), ag__\u001b[38;5;241m.\u001b[39mld(iterator)), \u001b[38;5;28;01mNone\u001b[39;00m, fscope)\n\u001b[0;32m     16\u001b[0m \u001b[38;5;28;01mexcept\u001b[39;00m:\n\u001b[0;32m     17\u001b[0m     do_return \u001b[38;5;241m=\u001b[39m \u001b[38;5;28;01mFalse\u001b[39;00m\n",
      "\u001b[1;31mValueError\u001b[0m: in user code:\n\n    File \"C:\\Users\\dalet\\anaconda3\\Lib\\site-packages\\keras\\src\\engine\\training.py\", line 2440, in predict_function  *\n        return step_function(self, iterator)\n    File \"C:\\Users\\dalet\\anaconda3\\Lib\\site-packages\\keras\\src\\engine\\training.py\", line 2425, in step_function  **\n        outputs = model.distribute_strategy.run(run_step, args=(data,))\n    File \"C:\\Users\\dalet\\anaconda3\\Lib\\site-packages\\keras\\src\\engine\\training.py\", line 2413, in run_step  **\n        outputs = model.predict_step(data)\n    File \"C:\\Users\\dalet\\anaconda3\\Lib\\site-packages\\keras\\src\\engine\\training.py\", line 2381, in predict_step\n        return self(x, training=False)\n    File \"C:\\Users\\dalet\\anaconda3\\Lib\\site-packages\\keras\\src\\utils\\traceback_utils.py\", line 70, in error_handler\n        raise e.with_traceback(filtered_tb) from None\n    File \"C:\\Users\\dalet\\anaconda3\\Lib\\site-packages\\keras\\src\\engine\\input_spec.py\", line 298, in assert_input_compatibility\n        raise ValueError(\n\n    ValueError: Input 0 of layer \"sequential\" is incompatible with the layer: expected shape=(None, 300, 300, 3), found shape=(None, 1022, 3)\n"
     ]
    }
   ],
   "source": [
    "model.predict(img_array)"
   ]
  },
  {
   "cell_type": "code",
   "execution_count": null,
   "id": "24518dcd-04a0-4740-9195-c9900bf50185",
   "metadata": {},
   "outputs": [],
   "source": []
  }
 ],
 "metadata": {
  "kernelspec": {
   "display_name": "Python 3 (ipykernel)",
   "language": "python",
   "name": "python3"
  },
  "language_info": {
   "codemirror_mode": {
    "name": "ipython",
    "version": 3
   },
   "file_extension": ".py",
   "mimetype": "text/x-python",
   "name": "python",
   "nbconvert_exporter": "python",
   "pygments_lexer": "ipython3",
   "version": "3.11.7"
  }
 },
 "nbformat": 4,
 "nbformat_minor": 5
}
